[2025-01-06T13:21:09.547+0000] {taskinstance.py:1956} INFO - Dependencies all met for dep_context=non-requeueable deps ti=<TaskInstance: insert_date.md_currency_d manual__2025-01-06T13:21:07.894411+00:00 [queued]>
[2025-01-06T13:21:09.560+0000] {taskinstance.py:1956} INFO - Dependencies all met for dep_context=requeueable deps ti=<TaskInstance: insert_date.md_currency_d manual__2025-01-06T13:21:07.894411+00:00 [queued]>
[2025-01-06T13:21:09.561+0000] {taskinstance.py:2170} INFO - Starting attempt 1 of 3
[2025-01-06T13:21:09.770+0000] {taskinstance.py:2191} INFO - Executing <Task(PythonOperator): md_currency_d> on 2025-01-06 13:21:07.894411+00:00
[2025-01-06T13:21:09.777+0000] {standard_task_runner.py:60} INFO - Started process 4226 to run task
[2025-01-06T13:21:09.781+0000] {standard_task_runner.py:87} INFO - Running: ['***', 'tasks', 'run', 'insert_date', 'md_currency_d', 'manual__2025-01-06T13:21:07.894411+00:00', '--job-id', '332', '--raw', '--subdir', 'DAGS_FOLDER/insert_data.py', '--cfg-path', '/tmp/tmp_xnzs_zb']
[2025-01-06T13:21:09.785+0000] {standard_task_runner.py:88} INFO - Job 332: Subtask md_currency_d
[2025-01-06T13:21:09.841+0000] {task_command.py:423} INFO - Running <TaskInstance: insert_date.md_currency_d manual__2025-01-06T13:21:07.894411+00:00 [running]> on host 25a397655cc7
[2025-01-06T13:21:09.935+0000] {taskinstance.py:2480} INFO - Exporting env vars: AIRFLOW_CTX_DAG_OWNER='budanovsa' AIRFLOW_CTX_DAG_ID='insert_date' AIRFLOW_CTX_TASK_ID='md_currency_d' AIRFLOW_CTX_EXECUTION_DATE='2025-01-06T13:21:07.894411+00:00' AIRFLOW_CTX_TRY_NUMBER='1' AIRFLOW_CTX_DAG_RUN_ID='manual__2025-01-06T13:21:07.894411+00:00'
[2025-01-06T13:21:09.940+0000] {taskinstance.py:2698} ERROR - Task failed with exception
Traceback (most recent call last):
  File "/home/airflow/.local/lib/python3.8/site-packages/airflow/models/taskinstance.py", line 433, in _execute_task
    result = execute_callable(context=context, **execute_callable_kwargs)
  File "/home/airflow/.local/lib/python3.8/site-packages/airflow/operators/python.py", line 199, in execute
    return_value = self.execute_callable()
  File "/home/airflow/.local/lib/python3.8/site-packages/airflow/operators/python.py", line 216, in execute_callable
    return self.python_callable(*self.op_args, **self.op_kwargs)
  File "/opt/airflow/dags/insert_data.py", line 16, in insert_data
    df = pandas.read_csv(PATH + f"{table_name}.csv", delimiter=";")
  File "/home/airflow/.local/lib/python3.8/site-packages/pandas/io/parsers/readers.py", line 912, in read_csv
    return _read(filepath_or_buffer, kwds)
  File "/home/airflow/.local/lib/python3.8/site-packages/pandas/io/parsers/readers.py", line 577, in _read
    parser = TextFileReader(filepath_or_buffer, **kwds)
  File "/home/airflow/.local/lib/python3.8/site-packages/pandas/io/parsers/readers.py", line 1407, in __init__
    self._engine = self._make_engine(f, self.engine)
  File "/home/airflow/.local/lib/python3.8/site-packages/pandas/io/parsers/readers.py", line 1679, in _make_engine
    return mapping[engine](f, **self.options)
  File "/home/airflow/.local/lib/python3.8/site-packages/pandas/io/parsers/c_parser_wrapper.py", line 93, in __init__
    self._reader = parsers.TextReader(src, **kwds)
  File "pandas/_libs/parsers.pyx", line 550, in pandas._libs.parsers.TextReader.__cinit__
  File "pandas/_libs/parsers.pyx", line 639, in pandas._libs.parsers.TextReader._get_header
  File "pandas/_libs/parsers.pyx", line 850, in pandas._libs.parsers.TextReader._tokenize_rows
  File "pandas/_libs/parsers.pyx", line 861, in pandas._libs.parsers.TextReader._check_tokenize_status
  File "pandas/_libs/parsers.pyx", line 2021, in pandas._libs.parsers.raise_parser_error
UnicodeDecodeError: 'utf-8' codec can't decode byte 0x98 in position 1189: invalid start byte
[2025-01-06T13:21:09.956+0000] {taskinstance.py:1138} INFO - Marking task as UP_FOR_RETRY. dag_id=insert_date, task_id=md_currency_d, execution_date=20250106T132107, start_date=20250106T132109, end_date=20250106T132109
[2025-01-06T13:21:09.981+0000] {standard_task_runner.py:107} ERROR - Failed to execute job 332 for task md_currency_d ('utf-8' codec can't decode byte 0x98 in position 1189: invalid start byte; 4226)
[2025-01-06T13:21:09.993+0000] {local_task_job_runner.py:234} INFO - Task exited with return code 1
[2025-01-06T13:21:10.014+0000] {taskinstance.py:3280} INFO - 0 downstream tasks scheduled from follow-on schedule check
