[2025-01-10T15:07:41.084+0000] {taskinstance.py:1956} INFO - Dependencies all met for dep_context=non-requeueable deps ti=<TaskInstance: insert_date.md_currency_d manual__2025-01-10T15:07:38.172897+00:00 [queued]>
[2025-01-10T15:07:41.099+0000] {taskinstance.py:1956} INFO - Dependencies all met for dep_context=requeueable deps ti=<TaskInstance: insert_date.md_currency_d manual__2025-01-10T15:07:38.172897+00:00 [queued]>
[2025-01-10T15:07:41.100+0000] {taskinstance.py:2170} INFO - Starting attempt 1 of 3
[2025-01-10T15:07:41.308+0000] {taskinstance.py:2191} INFO - Executing <Task(PythonOperator): md_currency_d> on 2025-01-10 15:07:38.172897+00:00
[2025-01-10T15:07:41.322+0000] {standard_task_runner.py:60} INFO - Started process 1284 to run task
[2025-01-10T15:07:41.331+0000] {standard_task_runner.py:87} INFO - Running: ['***', 'tasks', 'run', 'insert_date', 'md_currency_d', 'manual__2025-01-10T15:07:38.172897+00:00', '--job-id', '1568', '--raw', '--subdir', 'DAGS_FOLDER/insert_data.py', '--cfg-path', '/tmp/tmpjky1qrby']
[2025-01-10T15:07:41.335+0000] {standard_task_runner.py:88} INFO - Job 1568: Subtask md_currency_d
[2025-01-10T15:07:41.424+0000] {task_command.py:423} INFO - Running <TaskInstance: insert_date.md_currency_d manual__2025-01-10T15:07:38.172897+00:00 [running]> on host 711845a6becd
[2025-01-10T15:07:41.605+0000] {taskinstance.py:2480} INFO - Exporting env vars: AIRFLOW_CTX_DAG_OWNER='budanovsa' AIRFLOW_CTX_DAG_ID='insert_date' AIRFLOW_CTX_TASK_ID='md_currency_d' AIRFLOW_CTX_EXECUTION_DATE='2025-01-10T15:07:38.172897+00:00' AIRFLOW_CTX_TRY_NUMBER='1' AIRFLOW_CTX_DAG_RUN_ID='manual__2025-01-10T15:07:38.172897+00:00'
[2025-01-10T15:07:41.670+0000] {base.py:83} INFO - Using connection ID 'postgres-db' for task execution.
[2025-01-10T15:07:41.842+0000] {python.py:201} INFO - Done. Returned value was: None
[2025-01-10T15:07:41.854+0000] {taskinstance.py:1138} INFO - Marking task as SUCCESS. dag_id=insert_date, task_id=md_currency_d, execution_date=20250110T150738, start_date=20250110T150741, end_date=20250110T150741
[2025-01-10T15:07:41.860+0000] {base.py:83} INFO - Using connection ID 'postgres-db' for task execution.
[2025-01-10T15:07:41.935+0000] {sql.py:450} INFO - Running statement: 
        INSERT INTO log.logt (execution_datetime, event_datetime, event_name)
        VALUES ('2025-01-10T15:07:38.172897', '2025-01-10T15:07:41.855900', 'md_currency_d');
    , parameters: None
[2025-01-10T15:07:41.941+0000] {taskinstance.py:1116} ERROR - Error when executing uploading_logs callback
Traceback (most recent call last):
  File "/home/airflow/.local/lib/python3.8/site-packages/airflow/models/taskinstance.py", line 1113, in _run_finished_callback
    callback(context)
  File "/opt/airflow/dags/insert_data.py", line 51, in uploading_logs
    postgres_hook.run(query)
  File "/home/airflow/.local/lib/python3.8/site-packages/airflow/providers/common/sql/hooks/sql.py", line 398, in run
    self._run_command(cur, sql_statement, parameters)
  File "/home/airflow/.local/lib/python3.8/site-packages/airflow/providers/common/sql/hooks/sql.py", line 455, in _run_command
    cur.execute(sql_statement)
psycopg2.errors.UndefinedTable: ОШИБКА:  отношение "log.logt" не существует
LINE 2:         INSERT INTO log.logt (execution_datetime, event_date...
                            ^

[2025-01-10T15:07:41.992+0000] {local_task_job_runner.py:234} INFO - Task exited with return code 0
[2025-01-10T15:07:42.092+0000] {taskinstance.py:3280} INFO - 0 downstream tasks scheduled from follow-on schedule check
