[2025-01-15T09:06:07.919+0000] {taskinstance.py:1956} INFO - Dependencies all met for dep_context=non-requeueable deps ti=<TaskInstance: insert_date.ft_posting_f manual__2025-01-15T09:05:58.299864+00:00 [queued]>
[2025-01-15T09:06:07.941+0000] {taskinstance.py:1956} INFO - Dependencies all met for dep_context=requeueable deps ti=<TaskInstance: insert_date.ft_posting_f manual__2025-01-15T09:05:58.299864+00:00 [queued]>
[2025-01-15T09:06:07.942+0000] {taskinstance.py:2170} INFO - Starting attempt 1 of 3
[2025-01-15T09:06:08.604+0000] {taskinstance.py:2191} INFO - Executing <Task(PythonOperator): ft_posting_f> on 2025-01-15 09:05:58.299864+00:00
[2025-01-15T09:06:08.613+0000] {standard_task_runner.py:60} INFO - Started process 154 to run task
[2025-01-15T09:06:08.625+0000] {standard_task_runner.py:87} INFO - Running: ['***', 'tasks', 'run', 'insert_date', 'ft_posting_f', 'manual__2025-01-15T09:05:58.299864+00:00', '--job-id', '3131', '--raw', '--subdir', 'DAGS_FOLDER/insert_data.py', '--cfg-path', '/tmp/tmpo8c4h7ak']
[2025-01-15T09:06:08.656+0000] {standard_task_runner.py:88} INFO - Job 3131: Subtask ft_posting_f
[2025-01-15T09:06:09.116+0000] {task_command.py:423} INFO - Running <TaskInstance: insert_date.ft_posting_f manual__2025-01-15T09:05:58.299864+00:00 [running]> on host 711845a6becd
[2025-01-15T09:06:09.428+0000] {taskinstance.py:2480} INFO - Exporting env vars: AIRFLOW_CTX_DAG_OWNER='budanovsa' AIRFLOW_CTX_DAG_ID='insert_date' AIRFLOW_CTX_TASK_ID='ft_posting_f' AIRFLOW_CTX_EXECUTION_DATE='2025-01-15T09:05:58.299864+00:00' AIRFLOW_CTX_TRY_NUMBER='1' AIRFLOW_CTX_DAG_RUN_ID='manual__2025-01-15T09:05:58.299864+00:00'
[2025-01-15T09:06:09.441+0000] {taskinstance.py:2698} ERROR - Task failed with exception
Traceback (most recent call last):
  File "/home/airflow/.local/lib/python3.8/site-packages/airflow/models/taskinstance.py", line 433, in _execute_task
    result = execute_callable(context=context, **execute_callable_kwargs)
  File "/home/airflow/.local/lib/python3.8/site-packages/airflow/operators/python.py", line 199, in execute
    return_value = self.execute_callable()
  File "/home/airflow/.local/lib/python3.8/site-packages/airflow/operators/python.py", line 216, in execute_callable
    return self.python_callable(*self.op_args, **self.op_kwargs)
  File "/opt/airflow/dags/insert_data.py", line 22, in insert_data
    df = pandas.read_csv(PATH + f"{table_name}.csv", delimiter=";", encoding='utf-8')
  File "/home/airflow/.local/lib/python3.8/site-packages/pandas/io/parsers/readers.py", line 912, in read_csv
    return _read(filepath_or_buffer, kwds)
  File "/home/airflow/.local/lib/python3.8/site-packages/pandas/io/parsers/readers.py", line 577, in _read
    parser = TextFileReader(filepath_or_buffer, **kwds)
  File "/home/airflow/.local/lib/python3.8/site-packages/pandas/io/parsers/readers.py", line 1407, in __init__
    self._engine = self._make_engine(f, self.engine)
  File "/home/airflow/.local/lib/python3.8/site-packages/pandas/io/parsers/readers.py", line 1661, in _make_engine
    self.handles = get_handle(
  File "/home/airflow/.local/lib/python3.8/site-packages/pandas/io/common.py", line 868, in get_handle
    handle = open(handle, ioargs.mode)
FileNotFoundError: [Errno 2] No such file or directory: '/files/ft_posting_f.csv'
[2025-01-15T09:06:09.482+0000] {taskinstance.py:1138} INFO - Marking task as UP_FOR_RETRY. dag_id=insert_date, task_id=ft_posting_f, execution_date=20250115T090558, start_date=20250115T090607, end_date=20250115T090609
[2025-01-15T09:06:09.535+0000] {standard_task_runner.py:107} ERROR - Failed to execute job 3131 for task ft_posting_f ([Errno 2] No such file or directory: '/files/ft_posting_f.csv'; 154)
[2025-01-15T09:06:09.601+0000] {local_task_job_runner.py:234} INFO - Task exited with return code 1
[2025-01-15T09:06:09.723+0000] {taskinstance.py:3280} INFO - 0 downstream tasks scheduled from follow-on schedule check
