[2025-01-08T13:44:16.087+0000] {taskinstance.py:1956} INFO - Dependencies all met for dep_context=non-requeueable deps ti=<TaskInstance: insert_date.md_currency_d manual__2025-01-08T13:44:13.493152+00:00 [queued]>
[2025-01-08T13:44:16.102+0000] {taskinstance.py:1956} INFO - Dependencies all met for dep_context=requeueable deps ti=<TaskInstance: insert_date.md_currency_d manual__2025-01-08T13:44:13.493152+00:00 [queued]>
[2025-01-08T13:44:16.103+0000] {taskinstance.py:2170} INFO - Starting attempt 1 of 3
[2025-01-08T13:44:16.422+0000] {taskinstance.py:2191} INFO - Executing <Task(PythonOperator): md_currency_d> on 2025-01-08 13:44:13.493152+00:00
[2025-01-08T13:44:16.429+0000] {standard_task_runner.py:60} INFO - Started process 705 to run task
[2025-01-08T13:44:16.442+0000] {standard_task_runner.py:87} INFO - Running: ['***', 'tasks', 'run', 'insert_date', 'md_currency_d', 'manual__2025-01-08T13:44:13.493152+00:00', '--job-id', '1336', '--raw', '--subdir', 'DAGS_FOLDER/insert_data.py', '--cfg-path', '/tmp/tmphuqsj1m8']
[2025-01-08T13:44:16.450+0000] {standard_task_runner.py:88} INFO - Job 1336: Subtask md_currency_d
[2025-01-08T13:44:16.525+0000] {task_command.py:423} INFO - Running <TaskInstance: insert_date.md_currency_d manual__2025-01-08T13:44:13.493152+00:00 [running]> on host 779bfbde52bc
[2025-01-08T13:44:16.634+0000] {taskinstance.py:2480} INFO - Exporting env vars: AIRFLOW_CTX_DAG_OWNER='budanovsa' AIRFLOW_CTX_DAG_ID='insert_date' AIRFLOW_CTX_TASK_ID='md_currency_d' AIRFLOW_CTX_EXECUTION_DATE='2025-01-08T13:44:13.493152+00:00' AIRFLOW_CTX_TRY_NUMBER='1' AIRFLOW_CTX_DAG_RUN_ID='manual__2025-01-08T13:44:13.493152+00:00'
[2025-01-08T13:44:16.667+0000] {base.py:83} INFO - Using connection ID 'postgres-db' for task execution.
[2025-01-08T13:44:16.814+0000] {python.py:201} INFO - Done. Returned value was: None
[2025-01-08T13:44:16.828+0000] {taskinstance.py:1138} INFO - Marking task as SUCCESS. dag_id=insert_date, task_id=md_currency_d, execution_date=20250108T134413, start_date=20250108T134416, end_date=20250108T134416
[2025-01-08T13:44:16.839+0000] {base.py:83} INFO - Using connection ID 'postgres-db' for task execution.
[2025-01-08T13:44:16.923+0000] {sql.py:450} INFO - Running statement: 
        INSERT INTO log.logt (execution_datetime, event_datetime, event_name)
        VALUES ('2025-01-08T13:44:13.493152', '2025-01-08T13:44:16.829745', 'md_currency_d');
    , parameters: None
[2025-01-08T13:44:16.928+0000] {taskinstance.py:1116} ERROR - Error when executing uploading_logs callback
Traceback (most recent call last):
  File "/home/airflow/.local/lib/python3.8/site-packages/airflow/models/taskinstance.py", line 1113, in _run_finished_callback
    callback(context)
  File "/opt/airflow/dags/insert_data.py", line 50, in uploading_logs
    postgres_hook.run(query)
  File "/home/airflow/.local/lib/python3.8/site-packages/airflow/providers/common/sql/hooks/sql.py", line 398, in run
    self._run_command(cur, sql_statement, parameters)
  File "/home/airflow/.local/lib/python3.8/site-packages/airflow/providers/common/sql/hooks/sql.py", line 455, in _run_command
    cur.execute(sql_statement)
psycopg2.errors.UndefinedTable: ОШИБКА:  отношение "log.logt" не существует
LINE 2:         INSERT INTO log.logt (execution_datetime, event_date...
                            ^

[2025-01-08T13:44:16.977+0000] {local_task_job_runner.py:234} INFO - Task exited with return code 0
[2025-01-08T13:44:17.037+0000] {taskinstance.py:3280} INFO - 0 downstream tasks scheduled from follow-on schedule check
