[2025-01-12T14:03:26.642+0000] {taskinstance.py:1956} INFO - Dependencies all met for dep_context=non-requeueable deps ti=<TaskInstance: insert_date.start manual__2025-01-12T14:03:25.129209+00:00 [queued]>
[2025-01-12T14:03:26.649+0000] {taskinstance.py:1956} INFO - Dependencies all met for dep_context=requeueable deps ti=<TaskInstance: insert_date.start manual__2025-01-12T14:03:25.129209+00:00 [queued]>
[2025-01-12T14:03:26.650+0000] {taskinstance.py:2170} INFO - Starting attempt 1 of 3
[2025-01-12T14:03:26.764+0000] {taskinstance.py:2191} INFO - Executing <Task(EmptyOperator): start> on 2025-01-12 14:03:25.129209+00:00
[2025-01-12T14:03:26.769+0000] {standard_task_runner.py:60} INFO - Started process 1947 to run task
[2025-01-12T14:03:26.772+0000] {standard_task_runner.py:87} INFO - Running: ['***', 'tasks', 'run', 'insert_date', 'start', 'manual__2025-01-12T14:03:25.129209+00:00', '--job-id', '2183', '--raw', '--subdir', 'DAGS_FOLDER/insert_data.py', '--cfg-path', '/tmp/tmprky34cpb']
[2025-01-12T14:03:26.774+0000] {standard_task_runner.py:88} INFO - Job 2183: Subtask start
[2025-01-12T14:03:26.809+0000] {task_command.py:423} INFO - Running <TaskInstance: insert_date.start manual__2025-01-12T14:03:25.129209+00:00 [running]> on host 711845a6becd
[2025-01-12T14:03:26.863+0000] {taskinstance.py:2480} INFO - Exporting env vars: AIRFLOW_CTX_DAG_OWNER='budanovsa' AIRFLOW_CTX_DAG_ID='insert_date' AIRFLOW_CTX_TASK_ID='start' AIRFLOW_CTX_EXECUTION_DATE='2025-01-12T14:03:25.129209+00:00' AIRFLOW_CTX_TRY_NUMBER='1' AIRFLOW_CTX_DAG_RUN_ID='manual__2025-01-12T14:03:25.129209+00:00'
[2025-01-12T14:03:26.871+0000] {taskinstance.py:1138} INFO - Marking task as SUCCESS. dag_id=insert_date, task_id=start, execution_date=20250112T140325, start_date=20250112T140326, end_date=20250112T140326
[2025-01-12T14:03:26.874+0000] {base.py:83} INFO - Using connection ID 'postgres-db' for task execution.
[2025-01-12T14:03:26.912+0000] {sql.py:450} INFO - Running statement: 
        INSERT INTO log.logt (execution_datetime, event_datetime, event_name)
        VALUES ('2025-01-12 14:03:25.129209', '2025-01-12 14:03:26.871771', 'start');
    , parameters: None
[2025-01-12T14:03:26.915+0000] {taskinstance.py:1116} ERROR - Error when executing uploading_logs callback
Traceback (most recent call last):
  File "/home/airflow/.local/lib/python3.8/site-packages/airflow/models/taskinstance.py", line 1113, in _run_finished_callback
    callback(context)
  File "/opt/airflow/dags/insert_data.py", line 53, in uploading_logs
    postgres_hook.run(query)
  File "/home/airflow/.local/lib/python3.8/site-packages/airflow/providers/common/sql/hooks/sql.py", line 398, in run
    self._run_command(cur, sql_statement, parameters)
  File "/home/airflow/.local/lib/python3.8/site-packages/airflow/providers/common/sql/hooks/sql.py", line 455, in _run_command
    cur.execute(sql_statement)
psycopg2.errors.UndefinedTable: ОШИБКА:  отношение "log.logt" не существует
LINE 2:         INSERT INTO log.logt (execution_datetime, event_date...
                            ^

[2025-01-12T14:03:26.945+0000] {local_task_job_runner.py:234} INFO - Task exited with return code 0
[2025-01-12T14:03:26.967+0000] {taskinstance.py:3280} INFO - 8 downstream tasks scheduled from follow-on schedule check
