[2025-01-06T05:55:51.776+0000] {taskinstance.py:1956} INFO - Dependencies all met for dep_context=non-requeueable deps ti=<TaskInstance: insert_date.FT_POSTING_F manual__2025-01-06T05:55:49.326198+00:00 [queued]>
[2025-01-06T05:55:51.787+0000] {taskinstance.py:1956} INFO - Dependencies all met for dep_context=requeueable deps ti=<TaskInstance: insert_date.FT_POSTING_F manual__2025-01-06T05:55:49.326198+00:00 [queued]>
[2025-01-06T05:55:51.788+0000] {taskinstance.py:2170} INFO - Starting attempt 1 of 3
[2025-01-06T05:55:51.801+0000] {taskinstance.py:2191} INFO - Executing <Task(PythonOperator): FT_POSTING_F> on 2025-01-06 05:55:49.326198+00:00
[2025-01-06T05:55:51.806+0000] {standard_task_runner.py:60} INFO - Started process 385 to run task
[2025-01-06T05:55:51.810+0000] {standard_task_runner.py:87} INFO - Running: ['***', 'tasks', 'run', 'insert_date', 'FT_POSTING_F', 'manual__2025-01-06T05:55:49.326198+00:00', '--job-id', '88', '--raw', '--subdir', 'DAGS_FOLDER/insert_data.py', '--cfg-path', '/tmp/tmpb84xkowf']
[2025-01-06T05:55:51.814+0000] {standard_task_runner.py:88} INFO - Job 88: Subtask FT_POSTING_F
[2025-01-06T05:55:52.016+0000] {task_command.py:423} INFO - Running <TaskInstance: insert_date.FT_POSTING_F manual__2025-01-06T05:55:49.326198+00:00 [running]> on host 25a397655cc7
[2025-01-06T05:55:52.082+0000] {taskinstance.py:2480} INFO - Exporting env vars: AIRFLOW_CTX_DAG_OWNER='budanovsa' AIRFLOW_CTX_DAG_ID='insert_date' AIRFLOW_CTX_TASK_ID='FT_POSTING_F' AIRFLOW_CTX_EXECUTION_DATE='2025-01-06T05:55:49.326198+00:00' AIRFLOW_CTX_TRY_NUMBER='1' AIRFLOW_CTX_DAG_RUN_ID='manual__2025-01-06T05:55:49.326198+00:00'
[2025-01-06T05:55:52.085+0000] {taskinstance.py:2698} ERROR - Task failed with exception
Traceback (most recent call last):
  File "/home/airflow/.local/lib/python3.8/site-packages/airflow/models/taskinstance.py", line 433, in _execute_task
    result = execute_callable(context=context, **execute_callable_kwargs)
  File "/home/airflow/.local/lib/python3.8/site-packages/airflow/operators/python.py", line 199, in execute
    return_value = self.execute_callable()
  File "/home/airflow/.local/lib/python3.8/site-packages/airflow/operators/python.py", line 216, in execute_callable
    return self.python_callable(*self.op_args, **self.op_kwargs)
  File "/opt/airflow/dags/insert_data.py", line 11, in insert_data
    df = pandas.read_csv(f"/files/{table_name}.csv", delimiter=";")
  File "/home/airflow/.local/lib/python3.8/site-packages/pandas/io/parsers/readers.py", line 912, in read_csv
    return _read(filepath_or_buffer, kwds)
  File "/home/airflow/.local/lib/python3.8/site-packages/pandas/io/parsers/readers.py", line 577, in _read
    parser = TextFileReader(filepath_or_buffer, **kwds)
  File "/home/airflow/.local/lib/python3.8/site-packages/pandas/io/parsers/readers.py", line 1407, in __init__
    self._engine = self._make_engine(f, self.engine)
  File "/home/airflow/.local/lib/python3.8/site-packages/pandas/io/parsers/readers.py", line 1661, in _make_engine
    self.handles = get_handle(
  File "/home/airflow/.local/lib/python3.8/site-packages/pandas/io/common.py", line 859, in get_handle
    handle = open(
FileNotFoundError: [Errno 2] No such file or directory: '/files/FT_POSTING_F.csv'
[2025-01-06T05:55:52.094+0000] {taskinstance.py:1138} INFO - Marking task as UP_FOR_RETRY. dag_id=insert_date, task_id=FT_POSTING_F, execution_date=20250106T055549, start_date=20250106T055551, end_date=20250106T055552
[2025-01-06T05:55:52.107+0000] {standard_task_runner.py:107} ERROR - Failed to execute job 88 for task FT_POSTING_F ([Errno 2] No such file or directory: '/files/FT_POSTING_F.csv'; 385)
[2025-01-06T05:55:52.152+0000] {local_task_job_runner.py:234} INFO - Task exited with return code 1
[2025-01-06T05:55:52.282+0000] {taskinstance.py:3280} INFO - 0 downstream tasks scheduled from follow-on schedule check
[2025-01-06T09:21:21.826+0000] {taskinstance.py:1956} INFO - Dependencies all met for dep_context=non-requeueable deps ti=<TaskInstance: insert_date.ft_posting_f manual__2025-01-06T05:55:49.326198+00:00 [queued]>
[2025-01-06T09:21:21.833+0000] {taskinstance.py:1956} INFO - Dependencies all met for dep_context=requeueable deps ti=<TaskInstance: insert_date.ft_posting_f manual__2025-01-06T05:55:49.326198+00:00 [queued]>
[2025-01-06T09:21:21.834+0000] {taskinstance.py:2170} INFO - Starting attempt 1 of 3
[2025-01-06T09:21:21.844+0000] {taskinstance.py:2191} INFO - Executing <Task(PythonOperator): ft_posting_f> on 2025-01-06 05:55:49.326198+00:00
[2025-01-06T09:21:21.849+0000] {standard_task_runner.py:60} INFO - Started process 268 to run task
[2025-01-06T09:21:21.852+0000] {standard_task_runner.py:87} INFO - Running: ['***', 'tasks', 'run', 'insert_date', 'ft_posting_f', 'manual__2025-01-06T05:55:49.326198+00:00', '--job-id', '170', '--raw', '--subdir', 'DAGS_FOLDER/insert_data.py', '--cfg-path', '/tmp/tmpw2ukqs5c']
[2025-01-06T09:21:21.854+0000] {standard_task_runner.py:88} INFO - Job 170: Subtask ft_posting_f
[2025-01-06T09:21:22.006+0000] {task_command.py:423} INFO - Running <TaskInstance: insert_date.ft_posting_f manual__2025-01-06T05:55:49.326198+00:00 [running]> on host 25a397655cc7
[2025-01-06T09:21:22.063+0000] {taskinstance.py:2480} INFO - Exporting env vars: AIRFLOW_CTX_DAG_OWNER='budanovsa' AIRFLOW_CTX_DAG_ID='insert_date' AIRFLOW_CTX_TASK_ID='ft_posting_f' AIRFLOW_CTX_EXECUTION_DATE='2025-01-06T05:55:49.326198+00:00' AIRFLOW_CTX_TRY_NUMBER='1' AIRFLOW_CTX_DAG_RUN_ID='manual__2025-01-06T05:55:49.326198+00:00'
[2025-01-06T09:21:22.093+0000] {base.py:83} INFO - Using connection ID 'postgres-db' for task execution.
[2025-01-06T09:21:22.374+0000] {taskinstance.py:2698} ERROR - Task failed with exception
Traceback (most recent call last):
  File "/home/airflow/.local/lib/python3.8/site-packages/sqlalchemy/engine/base.py", line 1890, in _execute_context
    self.dialect.do_executemany(
  File "/home/airflow/.local/lib/python3.8/site-packages/sqlalchemy/dialects/postgresql/psycopg2.py", line 982, in do_executemany
    context._psycopg2_fetched_rows = xtras.execute_values(
  File "/home/airflow/.local/lib/python3.8/site-packages/psycopg2/extras.py", line 1299, in execute_values
    cur.execute(b''.join(parts))
psycopg2.errors.UndefinedColumn: ОШИБКА:  столбец "OPER_DATE" в таблице "ft_posting_f" не существует
LINE 1: INSERT INTO stage.ft_posting_f ("OPER_DATE", "CREDIT_ACCOUNT...
                                        ^


The above exception was the direct cause of the following exception:

Traceback (most recent call last):
  File "/home/airflow/.local/lib/python3.8/site-packages/airflow/models/taskinstance.py", line 433, in _execute_task
    result = execute_callable(context=context, **execute_callable_kwargs)
  File "/home/airflow/.local/lib/python3.8/site-packages/airflow/operators/python.py", line 199, in execute
    return_value = self.execute_callable()
  File "/home/airflow/.local/lib/python3.8/site-packages/airflow/operators/python.py", line 216, in execute_callable
    return self.python_callable(*self.op_args, **self.op_kwargs)
  File "/opt/airflow/dags/insert_data.py", line 14, in insert_data
    df.to_sql(table_name, engine, schema="stage", if_exists="append", index=False)
  File "/home/airflow/.local/lib/python3.8/site-packages/pandas/core/generic.py", line 2878, in to_sql
    return sql.to_sql(
  File "/home/airflow/.local/lib/python3.8/site-packages/pandas/io/sql.py", line 769, in to_sql
    return pandas_sql.to_sql(
  File "/home/airflow/.local/lib/python3.8/site-packages/pandas/io/sql.py", line 1920, in to_sql
    total_inserted = sql_engine.insert_records(
  File "/home/airflow/.local/lib/python3.8/site-packages/pandas/io/sql.py", line 1470, in insert_records
    raise err
  File "/home/airflow/.local/lib/python3.8/site-packages/pandas/io/sql.py", line 1461, in insert_records
    return table.insert(chunksize=chunksize, method=method)
  File "/home/airflow/.local/lib/python3.8/site-packages/pandas/io/sql.py", line 1023, in insert
    num_inserted = exec_insert(conn, keys, chunk_iter)
  File "/home/airflow/.local/lib/python3.8/site-packages/pandas/io/sql.py", line 929, in _execute_insert
    result = conn.execute(self.table.insert(), data)
  File "/home/airflow/.local/lib/python3.8/site-packages/sqlalchemy/engine/base.py", line 1385, in execute
    return meth(self, multiparams, params, _EMPTY_EXECUTION_OPTS)
  File "/home/airflow/.local/lib/python3.8/site-packages/sqlalchemy/sql/elements.py", line 334, in _execute_on_connection
    return connection._execute_clauseelement(
  File "/home/airflow/.local/lib/python3.8/site-packages/sqlalchemy/engine/base.py", line 1577, in _execute_clauseelement
    ret = self._execute_context(
  File "/home/airflow/.local/lib/python3.8/site-packages/sqlalchemy/engine/base.py", line 1953, in _execute_context
    self._handle_dbapi_exception(
  File "/home/airflow/.local/lib/python3.8/site-packages/sqlalchemy/engine/base.py", line 2134, in _handle_dbapi_exception
    util.raise_(
  File "/home/airflow/.local/lib/python3.8/site-packages/sqlalchemy/util/compat.py", line 211, in raise_
    raise exception
  File "/home/airflow/.local/lib/python3.8/site-packages/sqlalchemy/engine/base.py", line 1890, in _execute_context
    self.dialect.do_executemany(
  File "/home/airflow/.local/lib/python3.8/site-packages/sqlalchemy/dialects/postgresql/psycopg2.py", line 982, in do_executemany
    context._psycopg2_fetched_rows = xtras.execute_values(
  File "/home/airflow/.local/lib/python3.8/site-packages/psycopg2/extras.py", line 1299, in execute_values
    cur.execute(b''.join(parts))
sqlalchemy.exc.ProgrammingError: (psycopg2.errors.UndefinedColumn) ОШИБКА:  столбец "OPER_DATE" в таблице "ft_posting_f" не существует
LINE 1: INSERT INTO stage.ft_posting_f ("OPER_DATE", "CREDIT_ACCOUNT...
                                        ^

[SQL: INSERT INTO stage.ft_posting_f ("OPER_DATE", "CREDIT_ACCOUNT_RK", "DEBET_ACCOUNT_RK", "CREDIT_AMOUNT", "DEBET_AMOUNT") VALUES (%(OPER_DATE)s, %(CREDIT_ACCOUNT_RK)s, %(DEBET_ACCOUNT_RK)s, %(CREDIT_AMOUNT)s, %(DEBET_AMOUNT)s)]
[parameters: ({'OPER_DATE': '09-01-2018', 'CREDIT_ACCOUNT_RK': 13630, 'DEBET_ACCOUNT_RK': 17436, 'CREDIT_AMOUNT': 94333.93, 'DEBET_AMOUNT': 18337.76}, {'OPER_DATE': '09-01-2018', 'CREDIT_ACCOUNT_RK': 15698716, 'DEBET_ACCOUNT_RK': 13630, 'CREDIT_AMOUNT': 68294.14, 'DEBET_AMOUNT': 31542.06}, {'OPER_DATE': '09-01-2018', 'CREDIT_ACCOUNT_RK': 12048338, 'DEBET_ACCOUNT_RK': 13630, 'CREDIT_AMOUNT': 2192.96, 'DEBET_AMOUNT': 98734.33}, {'OPER_DATE': '09-01-2018', 'CREDIT_ACCOUNT_RK': 393808409, 'DEBET_ACCOUNT_RK': 17244, 'CREDIT_AMOUNT': 44179.86, 'DEBET_AMOUNT': 98544.65}, {'OPER_DATE': '09-01-2018', 'CREDIT_ACCOUNT_RK': 409685020, 'DEBET_ACCOUNT_RK': 13630, 'CREDIT_AMOUNT': 18843.05, 'DEBET_AMOUNT': 889.74}, {'OPER_DATE': '09-01-2018', 'CREDIT_ACCOUNT_RK': 10006159, 'DEBET_ACCOUNT_RK': 13630, 'CREDIT_AMOUNT': 82792.29, 'DEBET_AMOUNT': 15395.98}, {'OPER_DATE': '09-01-2018', 'CREDIT_ACCOUNT_RK': 393808409, 'DEBET_ACCOUNT_RK': 17132, 'CREDIT_AMOUNT': 9587.62, 'DEBET_AMOUNT': 40751.1}, {'OPER_DATE': '09-01-2018', 'CREDIT_ACCOUNT_RK': 23463, 'DEBET_ACCOUNT_RK': 13631, 'CREDIT_AMOUNT': 36873.02, 'DEBET_AMOUNT': 78441.61}  ... displaying 10 of 33892 total bound parameter sets ...  {'OPER_DATE': '31-01-2018', 'CREDIT_ACCOUNT_RK': 13630, 'DEBET_ACCOUNT_RK': 17627064, 'CREDIT_AMOUNT': 70839.11, 'DEBET_AMOUNT': 93751.76}, {'OPER_DATE': '31-01-2018', 'CREDIT_ACCOUNT_RK': 13630, 'DEBET_ACCOUNT_RK': 1648686, 'CREDIT_AMOUNT': 34785.31, 'DEBET_AMOUNT': 40997.1})]
(Background on this error at: https://sqlalche.me/e/14/f405)
[2025-01-06T09:21:22.386+0000] {taskinstance.py:1138} INFO - Marking task as UP_FOR_RETRY. dag_id=insert_date, task_id=ft_posting_f, execution_date=20250106T055549, start_date=20250106T092121, end_date=20250106T092122
[2025-01-06T09:21:22.398+0000] {standard_task_runner.py:107} ERROR - Failed to execute job 170 for task ft_posting_f ((psycopg2.errors.UndefinedColumn) ОШИБКА:  столбец "OPER_DATE" в таблице "ft_posting_f" не существует
LINE 1: INSERT INTO stage.ft_posting_f ("OPER_DATE", "CREDIT_ACCOUNT...
                                        ^

[SQL: INSERT INTO stage.ft_posting_f ("OPER_DATE", "CREDIT_ACCOUNT_RK", "DEBET_ACCOUNT_RK", "CREDIT_AMOUNT", "DEBET_AMOUNT") VALUES (%(OPER_DATE)s, %(CREDIT_ACCOUNT_RK)s, %(DEBET_ACCOUNT_RK)s, %(CREDIT_AMOUNT)s, %(DEBET_AMOUNT)s)]
[parameters: ({'OPER_DATE': '09-01-2018', 'CREDIT_ACCOUNT_RK': 13630, 'DEBET_ACCOUNT_RK': 17436, 'CREDIT_AMOUNT': 94333.93, 'DEBET_AMOUNT': 18337.76}, {'OPER_DATE': '09-01-2018', 'CREDIT_ACCOUNT_RK': 15698716, 'DEBET_ACCOUNT_RK': 13630, 'CREDIT_AMOUNT': 68294.14, 'DEBET_AMOUNT': 31542.06}, {'OPER_DATE': '09-01-2018', 'CREDIT_ACCOUNT_RK': 12048338, 'DEBET_ACCOUNT_RK': 13630, 'CREDIT_AMOUNT': 2192.96, 'DEBET_AMOUNT': 98734.33}, {'OPER_DATE': '09-01-2018', 'CREDIT_ACCOUNT_RK': 393808409, 'DEBET_ACCOUNT_RK': 17244, 'CREDIT_AMOUNT': 44179.86, 'DEBET_AMOUNT': 98544.65}, {'OPER_DATE': '09-01-2018', 'CREDIT_ACCOUNT_RK': 409685020, 'DEBET_ACCOUNT_RK': 13630, 'CREDIT_AMOUNT': 18843.05, 'DEBET_AMOUNT': 889.74}, {'OPER_DATE': '09-01-2018', 'CREDIT_ACCOUNT_RK': 10006159, 'DEBET_ACCOUNT_RK': 13630, 'CREDIT_AMOUNT': 82792.29, 'DEBET_AMOUNT': 15395.98}, {'OPER_DATE': '09-01-2018', 'CREDIT_ACCOUNT_RK': 393808409, 'DEBET_ACCOUNT_RK': 17132, 'CREDIT_AMOUNT': 9587.62, 'DEBET_AMOUNT': 40751.1}, {'OPER_DATE': '09-01-2018', 'CREDIT_ACCOUNT_RK': 23463, 'DEBET_ACCOUNT_RK': 13631, 'CREDIT_AMOUNT': 36873.02, 'DEBET_AMOUNT': 78441.61}  ... displaying 10 of 33892 total bound parameter sets ...  {'OPER_DATE': '31-01-2018', 'CREDIT_ACCOUNT_RK': 13630, 'DEBET_ACCOUNT_RK': 17627064, 'CREDIT_AMOUNT': 70839.11, 'DEBET_AMOUNT': 93751.76}, {'OPER_DATE': '31-01-2018', 'CREDIT_ACCOUNT_RK': 13630, 'DEBET_ACCOUNT_RK': 1648686, 'CREDIT_AMOUNT': 34785.31, 'DEBET_AMOUNT': 40997.1})]
(Background on this error at: https://sqlalche.me/e/14/f405); 268)
[2025-01-06T09:21:22.426+0000] {local_task_job_runner.py:234} INFO - Task exited with return code 1
[2025-01-06T09:21:22.571+0000] {taskinstance.py:3280} INFO - 0 downstream tasks scheduled from follow-on schedule check
