[2025-01-10T14:22:42.429+0000] {taskinstance.py:1946} INFO - Dependencies not met for <TaskInstance: insert_date.create_log_sheme manual__2025-01-10T14:22:19.609079+00:00 [None]>, dependency 'Trigger Rule' FAILED: Task's trigger rule 'all_success' requires all upstream tasks to have succeeded, but found 1 non-success(es). upstream_states=_UpstreamTIStates(success=0, skipped=0, failed=0, upstream_failed=0, removed=0, done=0, success_setup=0, skipped_setup=0), upstream_task_ids={'start'}
[2025-01-10T14:22:42.434+0000] {local_task_job_runner.py:160} INFO - Task is not able to be run
[2025-01-10T14:22:44.075+0000] {taskinstance.py:1956} INFO - Dependencies all met for dep_context=non-requeueable deps ti=<TaskInstance: insert_date.create_log_sheme manual__2025-01-10T14:22:19.609079+00:00 [queued]>
[2025-01-10T14:22:44.087+0000] {taskinstance.py:1956} INFO - Dependencies all met for dep_context=requeueable deps ti=<TaskInstance: insert_date.create_log_sheme manual__2025-01-10T14:22:19.609079+00:00 [queued]>
[2025-01-10T14:22:44.088+0000] {taskinstance.py:2170} INFO - Starting attempt 2 of 4
[2025-01-10T14:22:44.259+0000] {taskinstance.py:2191} INFO - Executing <Task(SQLExecuteQueryOperator): create_log_sheme> on 2025-01-10 14:22:19.609079+00:00
[2025-01-10T14:22:44.267+0000] {standard_task_runner.py:60} INFO - Started process 317 to run task
[2025-01-10T14:22:44.271+0000] {standard_task_runner.py:87} INFO - Running: ['***', 'tasks', 'run', 'insert_date', 'create_log_sheme', 'manual__2025-01-10T14:22:19.609079+00:00', '--job-id', '1463', '--raw', '--subdir', 'DAGS_FOLDER/insert_data.py', '--cfg-path', '/tmp/tmp0b2hyngf']
[2025-01-10T14:22:44.276+0000] {standard_task_runner.py:88} INFO - Job 1463: Subtask create_log_sheme
[2025-01-10T14:22:44.345+0000] {task_command.py:423} INFO - Running <TaskInstance: insert_date.create_log_sheme manual__2025-01-10T14:22:19.609079+00:00 [running]> on host 711845a6becd
[2025-01-10T14:22:44.445+0000] {taskinstance.py:2480} INFO - Exporting env vars: AIRFLOW_CTX_DAG_OWNER='budanovsa' AIRFLOW_CTX_DAG_ID='insert_date' AIRFLOW_CTX_TASK_ID='create_log_sheme' AIRFLOW_CTX_EXECUTION_DATE='2025-01-10T14:22:19.609079+00:00' AIRFLOW_CTX_TRY_NUMBER='2' AIRFLOW_CTX_DAG_RUN_ID='manual__2025-01-10T14:22:19.609079+00:00'
[2025-01-10T14:22:44.446+0000] {sql.py:276} INFO - Executing: create schema if not exists "logs";

create table if not exists
	logs.csv_to_dag (
		execution_datetime TIMESTAMP not null,
		event_datetime TIMESTAMP not null,
		event_name VARCHAR(30) not null,
		event_status VARCHAR(30)
);
[2025-01-10T14:22:44.458+0000] {base.py:83} INFO - Using connection ID 'postgres-db' for task execution.
[2025-01-10T14:22:44.469+0000] {base.py:83} INFO - Using connection ID 'postgres-db' for task execution.
[2025-01-10T14:22:44.541+0000] {sql.py:450} INFO - Running statement: create schema if not exists "logs";

create table if not exists
	logs.csv_to_dag (
		execution_datetime TIMESTAMP not null,
		event_datetime TIMESTAMP not null,
		event_name VARCHAR(30) not null,
		event_status VARCHAR(30)
);, parameters: None
[2025-01-10T14:22:44.558+0000] {taskinstance.py:1138} INFO - Marking task as SUCCESS. dag_id=insert_date, task_id=create_log_sheme, execution_date=20250110T142219, start_date=20250110T142244, end_date=20250110T142244
[2025-01-10T14:22:44.565+0000] {base.py:83} INFO - Using connection ID 'postgres-db' for task execution.
[2025-01-10T14:22:44.646+0000] {sql.py:450} INFO - Running statement: 
        INSERT INTO log.logt (execution_datetime, event_datetime, event_name)
        VALUES ('2025-01-10T14:22:19.609079', '2025-01-10T14:22:44.559785', 'create_log_sheme');
    , parameters: None
[2025-01-10T14:22:44.655+0000] {taskinstance.py:1116} ERROR - Error when executing uploading_logs callback
Traceback (most recent call last):
  File "/home/airflow/.local/lib/python3.8/site-packages/airflow/models/taskinstance.py", line 1113, in _run_finished_callback
    callback(context)
  File "/opt/airflow/dags/insert_data.py", line 50, in uploading_logs
    postgres_hook.run(query)
  File "/home/airflow/.local/lib/python3.8/site-packages/airflow/providers/common/sql/hooks/sql.py", line 398, in run
    self._run_command(cur, sql_statement, parameters)
  File "/home/airflow/.local/lib/python3.8/site-packages/airflow/providers/common/sql/hooks/sql.py", line 455, in _run_command
    cur.execute(sql_statement)
psycopg2.errors.UndefinedTable: ОШИБКА:  отношение "log.logt" не существует
LINE 2:         INSERT INTO log.logt (execution_datetime, event_date...
                            ^

[2025-01-10T14:22:44.725+0000] {local_task_job_runner.py:234} INFO - Task exited with return code 0
[2025-01-10T14:22:44.760+0000] {taskinstance.py:3280} INFO - 0 downstream tasks scheduled from follow-on schedule check
