[2025-01-10T15:46:36.069+0000] {taskinstance.py:1956} INFO - Dependencies all met for dep_context=non-requeueable deps ti=<TaskInstance: insert_date.md_currency_d manual__2025-01-10T15:46:33.572907+00:00 [queued]>
[2025-01-10T15:46:36.089+0000] {taskinstance.py:1956} INFO - Dependencies all met for dep_context=requeueable deps ti=<TaskInstance: insert_date.md_currency_d manual__2025-01-10T15:46:33.572907+00:00 [queued]>
[2025-01-10T15:46:36.089+0000] {taskinstance.py:2170} INFO - Starting attempt 1 of 3
[2025-01-10T15:46:36.294+0000] {taskinstance.py:2191} INFO - Executing <Task(PythonOperator): md_currency_d> on 2025-01-10 15:46:33.572907+00:00
[2025-01-10T15:46:36.300+0000] {standard_task_runner.py:60} INFO - Started process 2414 to run task
[2025-01-10T15:46:36.307+0000] {standard_task_runner.py:87} INFO - Running: ['***', 'tasks', 'run', 'insert_date', 'md_currency_d', 'manual__2025-01-10T15:46:33.572907+00:00', '--job-id', '1765', '--raw', '--subdir', 'DAGS_FOLDER/insert_data.py', '--cfg-path', '/tmp/tmplqm9ru04']
[2025-01-10T15:46:36.310+0000] {standard_task_runner.py:88} INFO - Job 1765: Subtask md_currency_d
[2025-01-10T15:46:36.372+0000] {task_command.py:423} INFO - Running <TaskInstance: insert_date.md_currency_d manual__2025-01-10T15:46:33.572907+00:00 [running]> on host 711845a6becd
[2025-01-10T15:46:36.472+0000] {taskinstance.py:2480} INFO - Exporting env vars: AIRFLOW_CTX_DAG_OWNER='budanovsa' AIRFLOW_CTX_DAG_ID='insert_date' AIRFLOW_CTX_TASK_ID='md_currency_d' AIRFLOW_CTX_EXECUTION_DATE='2025-01-10T15:46:33.572907+00:00' AIRFLOW_CTX_TRY_NUMBER='1' AIRFLOW_CTX_DAG_RUN_ID='manual__2025-01-10T15:46:33.572907+00:00'
[2025-01-10T15:46:36.502+0000] {base.py:83} INFO - Using connection ID 'postgres-db' for task execution.
[2025-01-10T15:46:36.504+0000] {taskinstance.py:2698} ERROR - Task failed with exception
Traceback (most recent call last):
  File "/home/airflow/.local/lib/python3.8/site-packages/airflow/models/taskinstance.py", line 433, in _execute_task
    result = execute_callable(context=context, **execute_callable_kwargs)
  File "/home/airflow/.local/lib/python3.8/site-packages/airflow/operators/python.py", line 199, in execute
    return_value = self.execute_callable()
  File "/home/airflow/.local/lib/python3.8/site-packages/airflow/operators/python.py", line 216, in execute_callable
    return self.python_callable(*self.op_args, **self.op_kwargs)
  File "/opt/airflow/dags/insert_data.py", line 34, in insert_data
    df.to_sql(table_name, engine, schema="stage", if_exists="reduce", index=False)
  File "/home/airflow/.local/lib/python3.8/site-packages/pandas/core/generic.py", line 2878, in to_sql
    return sql.to_sql(
  File "/home/airflow/.local/lib/python3.8/site-packages/pandas/io/sql.py", line 759, in to_sql
    raise ValueError(f"'{if_exists}' is not valid for if_exists")
ValueError: 'reduce' is not valid for if_exists
[2025-01-10T15:46:36.529+0000] {taskinstance.py:1138} INFO - Marking task as UP_FOR_RETRY. dag_id=insert_date, task_id=md_currency_d, execution_date=20250110T154633, start_date=20250110T154636, end_date=20250110T154636
[2025-01-10T15:46:36.546+0000] {standard_task_runner.py:107} ERROR - Failed to execute job 1765 for task md_currency_d ('reduce' is not valid for if_exists; 2414)
[2025-01-10T15:46:36.563+0000] {local_task_job_runner.py:234} INFO - Task exited with return code 1
[2025-01-10T15:46:36.667+0000] {taskinstance.py:3280} INFO - 0 downstream tasks scheduled from follow-on schedule check
