[2025-01-27T20:31:18.679+0000] {taskinstance.py:1956} INFO - Dependencies all met for dep_context=non-requeueable deps ti=<TaskInstance: import_date.start manual__2025-01-27T20:31:17.541291+00:00 [queued]>
[2025-01-27T20:31:18.687+0000] {taskinstance.py:1956} INFO - Dependencies all met for dep_context=requeueable deps ti=<TaskInstance: import_date.start manual__2025-01-27T20:31:17.541291+00:00 [queued]>
[2025-01-27T20:31:18.688+0000] {taskinstance.py:2170} INFO - Starting attempt 1 of 3
[2025-01-27T20:31:18.815+0000] {taskinstance.py:2191} INFO - Executing <Task(EmptyOperator): start> on 2025-01-27 20:31:17.541291+00:00
[2025-01-27T20:31:18.820+0000] {standard_task_runner.py:60} INFO - Started process 1618 to run task
[2025-01-27T20:31:18.823+0000] {standard_task_runner.py:87} INFO - Running: ['***', 'tasks', 'run', 'import_date', 'start', 'manual__2025-01-27T20:31:17.541291+00:00', '--job-id', '3327', '--raw', '--subdir', 'DAGS_FOLDER/import_date.py', '--cfg-path', '/tmp/tmpmqwo4kzj']
[2025-01-27T20:31:18.826+0000] {standard_task_runner.py:88} INFO - Job 3327: Subtask start
[2025-01-27T20:31:18.868+0000] {task_command.py:423} INFO - Running <TaskInstance: import_date.start manual__2025-01-27T20:31:17.541291+00:00 [running]> on host 711845a6becd
[2025-01-27T20:31:18.944+0000] {taskinstance.py:2480} INFO - Exporting env vars: AIRFLOW_CTX_DAG_OWNER='budanovsa' AIRFLOW_CTX_DAG_ID='import_date' AIRFLOW_CTX_TASK_ID='start' AIRFLOW_CTX_EXECUTION_DATE='2025-01-27T20:31:17.541291+00:00' AIRFLOW_CTX_TRY_NUMBER='1' AIRFLOW_CTX_DAG_RUN_ID='manual__2025-01-27T20:31:17.541291+00:00'
[2025-01-27T20:31:18.954+0000] {taskinstance.py:1138} INFO - Marking task as SUCCESS. dag_id=import_date, task_id=start, execution_date=20250127T203117, start_date=20250127T203118, end_date=20250127T203118
[2025-01-27T20:31:18.955+0000] {taskinstance.py:1116} ERROR - Error when executing uploading_logs callback
Traceback (most recent call last):
  File "/home/airflow/.local/lib/python3.8/site-packages/airflow/models/taskinstance.py", line 1113, in _run_finished_callback
    callback(context)
TypeError: uploading_logs() takes 0 positional arguments but 1 was given
[2025-01-27T20:31:18.997+0000] {local_task_job_runner.py:234} INFO - Task exited with return code 0
[2025-01-27T20:31:19.018+0000] {taskinstance.py:3280} INFO - 1 downstream tasks scheduled from follow-on schedule check
