[2025-01-27T19:29:10.966+0000] {taskinstance.py:1956} INFO - Dependencies all met for dep_context=non-requeueable deps ti=<TaskInstance: import_date.import_date manual__2025-01-27T19:29:08.206646+00:00 [queued]>
[2025-01-27T19:29:10.979+0000] {taskinstance.py:1956} INFO - Dependencies all met for dep_context=requeueable deps ti=<TaskInstance: import_date.import_date manual__2025-01-27T19:29:08.206646+00:00 [queued]>
[2025-01-27T19:29:10.979+0000] {taskinstance.py:2170} INFO - Starting attempt 1 of 3
[2025-01-27T19:29:10.995+0000] {taskinstance.py:2191} INFO - Executing <Task(PythonOperator): import_date> on 2025-01-27 19:29:08.206646+00:00
[2025-01-27T19:29:11.002+0000] {standard_task_runner.py:60} INFO - Started process 477 to run task
[2025-01-27T19:29:11.005+0000] {standard_task_runner.py:87} INFO - Running: ['***', 'tasks', 'run', 'import_date', 'import_date', 'manual__2025-01-27T19:29:08.206646+00:00', '--job-id', '3256', '--raw', '--subdir', 'DAGS_FOLDER/import_date.py', '--cfg-path', '/tmp/tmp93n3nvrp']
[2025-01-27T19:29:11.186+0000] {standard_task_runner.py:88} INFO - Job 3256: Subtask import_date
[2025-01-27T19:29:11.231+0000] {task_command.py:423} INFO - Running <TaskInstance: import_date.import_date manual__2025-01-27T19:29:08.206646+00:00 [running]> on host 711845a6becd
[2025-01-27T19:29:11.298+0000] {taskinstance.py:2480} INFO - Exporting env vars: AIRFLOW_CTX_DAG_OWNER='budanovsa' AIRFLOW_CTX_DAG_ID='import_date' AIRFLOW_CTX_TASK_ID='import_date' AIRFLOW_CTX_EXECUTION_DATE='2025-01-27T19:29:08.206646+00:00' AIRFLOW_CTX_TRY_NUMBER='1' AIRFLOW_CTX_DAG_RUN_ID='manual__2025-01-27T19:29:08.206646+00:00'
[2025-01-27T19:29:11.299+0000] {taskinstance.py:2698} ERROR - Task failed with exception
Traceback (most recent call last):
  File "/home/airflow/.local/lib/python3.8/site-packages/airflow/models/taskinstance.py", line 433, in _execute_task
    result = execute_callable(context=context, **execute_callable_kwargs)
  File "/home/airflow/.local/lib/python3.8/site-packages/airflow/operators/python.py", line 199, in execute
    return_value = self.execute_callable()
  File "/home/airflow/.local/lib/python3.8/site-packages/airflow/operators/python.py", line 216, in execute_callable
    return self.python_callable(*self.op_args, **self.op_kwargs)
TypeError: import_date() missing 1 required positional argument: 'table_name'
[2025-01-27T19:29:11.305+0000] {taskinstance.py:1138} INFO - Marking task as UP_FOR_RETRY. dag_id=import_date, task_id=import_date, execution_date=20250127T192908, start_date=20250127T192910, end_date=20250127T192911
[2025-01-27T19:29:11.315+0000] {standard_task_runner.py:107} ERROR - Failed to execute job 3256 for task import_date (import_date() missing 1 required positional argument: 'table_name'; 477)
[2025-01-27T19:29:11.340+0000] {local_task_job_runner.py:234} INFO - Task exited with return code 1
[2025-01-27T19:29:11.509+0000] {taskinstance.py:3280} INFO - 0 downstream tasks scheduled from follow-on schedule check
