[2025-01-12T19:53:18.349+0000] {taskinstance.py:1956} INFO - Dependencies all met for dep_context=non-requeueable deps ti=<TaskInstance: insert_date.md_ledger_account_s manual__2025-01-12T19:53:08.795826+00:00 [queued]>
[2025-01-12T19:53:18.364+0000] {taskinstance.py:1956} INFO - Dependencies all met for dep_context=requeueable deps ti=<TaskInstance: insert_date.md_ledger_account_s manual__2025-01-12T19:53:08.795826+00:00 [queued]>
[2025-01-12T19:53:18.365+0000] {taskinstance.py:2170} INFO - Starting attempt 1 of 3
[2025-01-12T19:53:18.598+0000] {taskinstance.py:2191} INFO - Executing <Task(PythonOperator): md_ledger_account_s> on 2025-01-12 19:53:08.795826+00:00
[2025-01-12T19:53:18.605+0000] {standard_task_runner.py:60} INFO - Started process 8102 to run task
[2025-01-12T19:53:18.610+0000] {standard_task_runner.py:87} INFO - Running: ['***', 'tasks', 'run', 'insert_date', 'md_ledger_account_s', 'manual__2025-01-12T19:53:08.795826+00:00', '--job-id', '2808', '--raw', '--subdir', 'DAGS_FOLDER/insert_data.py', '--cfg-path', '/tmp/tmpp2zjb6n6']
[2025-01-12T19:53:18.615+0000] {standard_task_runner.py:88} INFO - Job 2808: Subtask md_ledger_account_s
[2025-01-12T19:53:18.682+0000] {task_command.py:423} INFO - Running <TaskInstance: insert_date.md_ledger_account_s manual__2025-01-12T19:53:08.795826+00:00 [running]> on host 711845a6becd
[2025-01-12T19:53:18.789+0000] {taskinstance.py:2480} INFO - Exporting env vars: AIRFLOW_CTX_DAG_OWNER='budanovsa' AIRFLOW_CTX_DAG_ID='insert_date' AIRFLOW_CTX_TASK_ID='md_ledger_account_s' AIRFLOW_CTX_EXECUTION_DATE='2025-01-12T19:53:08.795826+00:00' AIRFLOW_CTX_TRY_NUMBER='1' AIRFLOW_CTX_DAG_RUN_ID='manual__2025-01-12T19:53:08.795826+00:00'
[2025-01-12T19:53:18.797+0000] {taskinstance.py:2698} ERROR - Task failed with exception
Traceback (most recent call last):
  File "/home/airflow/.local/lib/python3.8/site-packages/airflow/models/taskinstance.py", line 433, in _execute_task
    result = execute_callable(context=context, **execute_callable_kwargs)
  File "/home/airflow/.local/lib/python3.8/site-packages/airflow/operators/python.py", line 199, in execute
    return_value = self.execute_callable()
  File "/home/airflow/.local/lib/python3.8/site-packages/airflow/operators/python.py", line 216, in execute_callable
    return self.python_callable(*self.op_args, **self.op_kwargs)
  File "/opt/airflow/dags/insert_data.py", line 25, in insert_data
    df.to_sql(table_name, engine, schema="stage", if_exists="reduce", index=False)
  File "/home/airflow/.local/lib/python3.8/site-packages/pandas/core/generic.py", line 2878, in to_sql
    return sql.to_sql(
  File "/home/airflow/.local/lib/python3.8/site-packages/pandas/io/sql.py", line 759, in to_sql
    raise ValueError(f"'{if_exists}' is not valid for if_exists")
ValueError: 'reduce' is not valid for if_exists
[2025-01-12T19:53:18.814+0000] {taskinstance.py:1138} INFO - Marking task as UP_FOR_RETRY. dag_id=insert_date, task_id=md_ledger_account_s, execution_date=20250112T195308, start_date=20250112T195318, end_date=20250112T195318
[2025-01-12T19:53:18.829+0000] {standard_task_runner.py:107} ERROR - Failed to execute job 2808 for task md_ledger_account_s ('reduce' is not valid for if_exists; 8102)
[2025-01-12T19:53:18.866+0000] {local_task_job_runner.py:234} INFO - Task exited with return code 1
[2025-01-12T19:53:18.959+0000] {taskinstance.py:3280} INFO - 0 downstream tasks scheduled from follow-on schedule check
